<?xml version="1.0"?>
<robot xmlns:xacro="http://www.ros.org/wiki/xacro"  name="robot">


    <material name="c_base">
        <color rgba="0.506 0.031 0.98 0.8"/>
    </material>

    <material name="white">
        <color rgba="1 1 1 1"/>
    </material>

    <material name="gray_j_side">
        <color rgba="0.5 0.5 0.5 0.6"/>
    </material>

    <material name="c_l1">
        <color rgba="0 1 1 0.8"/>
    </material>

    <material name="c_l2">
        <color rgba="0 0.617 0.579 0.8"/>
    </material>

    <material name="c_l3">
        <color rgba="0 0.778 0.742 1"/>
    </material>

    <material name="c_g">
        <color rgba="0.05 0.5 0.1 1"/>
    </material>



    <link name="world"></link>

    <joint name="world_to_base" type="prismatic">
        <parent link="world" />
        <child link="base" />
        <origin xyz="1.0 0 0" rpy="1.57 0 0" />
         <axis rpy="0 0 0" xyz="1 0 0" />
        <limit effort="0.1" lower="-3.0" upper="3.0" velocity="0.2"/>
    </joint>

    <link name="base">
        <visual>
            <origin xyz="0 0 0" rpy="1.57 0 0"/>
            <geometry>
                 <box size="0.5 0.5 0.125" />
            </geometry>
            <material name="c_base" />
        </visual>
    </link>


    <joint name="base_to_l1" type="revolute">
        <parent link="base" />
        <child link="l1" />
        <origin xyz="0 0.1 0" rpy="1.57 0 0"  />
        <axis xyz="0 0 1" />
        <limit effort="0.1" lower="-3.14" upper="3.14" velocity="0.2"/>
    </joint>


    <link name="l1">
        <visual>
            <origin xyz="0.0 0 0" rpy="0 0 1.57"/>
            <geometry>
                 <cylinder length="0.05" radius="0.1" />
            </geometry>
            <material name="gray_j_side" />
        </visual>
        <visual>
            <origin xyz="0 0 -0.5" rpy="0 0 1.57"/>
            <geometry>
                <cylinder length="1.0" radius="0.04" />
            </geometry>
            <material name="c_l1" />
        </visual>
    </link>


       <joint name="l1_to_l2" type="revolute">
        <parent link="l1" />
        <child link="l2" />
        <origin xyz="0 0 -1.0" rpy="1.57 0 0" />
        <axis xyz="0 0 1" />
        <limit effort="0.1" lower="0.3" upper="-0.7" velocity="0.2"/>
    </joint>


    <link name="l2">
        <visual>
            <origin xyz="0.0 0 0" rpy="0 0 0"/>
            <geometry>
                 <cylinder length="0.05" radius="0.1" />
            </geometry>
            <material name="gray_j_side" />
        </visual>
        <visual>
            <origin xyz="0.3 0 0" rpy="0 1.57 0 "/>
            <geometry>
                <cylinder length="0.6" radius="0.04" />
            </geometry>
            <material name="c_l2" />
        </visual>
    </link>

    <joint name="l2_to_l3" type="revolute">
        <parent link="l2" />
        <child link="l3" />
        <origin xyz="0.6 0 0" rpy="0 1.57 0"/>
        <axis  xyz="0 0 1" />
        <limit effort="0.1" lower="-1.57" upper="1.57" velocity="0.2"/>
    </joint>


    <link name="l3">
        <visual>
            <origin xyz="0.0 0 0" rpy="0 0 0"/>
            <geometry>
                 <cylinder length="0.05" radius="0.1" />
            </geometry>
            <material name="gray_j_side" />
        </visual>
        <visual>
            <origin xyz="0 0.2 0" rpy="0 1.57 1.57"/>
            <geometry>
                <cylinder length="0.4" radius="0.04" />
            </geometry>
            <material name="c_l3" />
        </visual>
    </link>


    <joint name="l3_to_grip_base" type="revolute">
        <parent link="l3" />
        <child link="grip_base" />
        <origin xyz="0 0.4 0" rpy="0 1.57 0"  />
        <axis xyz="0 0 1" />
        <limit effort="0.1" lower="-1.57" upper="1.57" velocity="0.2"/>
    </joint>


    <link name="grip_base">
        <visual>
            <origin xyz="0.0 0 0" rpy="0 0 0"/>
            <geometry>
                 <cylinder length="0.05" radius="0.1" />
            </geometry>
            <material name="gray_j_side" />
        </visual>
        <visual>
            <origin xyz="0 0.15 0" rpy="0 1.57 1.57" />
            <geometry>
                <cylinder length="0.35" radius="0.04" />
            </geometry>
            <material name="c_g" />
        </visual>
    </link>


    <joint name="gripbase_to_gripper" type="revolute">
        <parent link="grip_base" />
        <child link="gripper" />
        <origin xyz="0 0.3 0" rpy="1.57 0 0" />
        <axis xyz="0 0 1" />
        <limit effort="0.1" lower="-1.5" upper="1.5" velocity="0.2"/>
    </joint>

    <link name="gripper">
        <visual>
            <origin xyz="0.0 0 0" rpy="0 0 0"/>
            <geometry>
                <cylinder length="0.05" radius="0.1" />
            </geometry>
            <material name="gray_j_side" />
        </visual>
         <visual>
            <origin xyz="0 0 -0.05" rpy="0 1.57 0" />
            <geometry>
                <box size="0.05 0.07 0.04" />
            </geometry>
            <material name="white" />
        </visual>
        <visual>
            <origin xyz="0.0 -0.07 -0.125" rpy="0 1.57 0" />
            <geometry>
                <box size="0.2 0.07 0.04" />
            </geometry>
            <material name="white" />
        </visual>
        <visual>
            <origin xyz="0.0 0.07 -0.125" rpy="0 1.57 0" />
            <geometry>
                <box size="0.2 0.07 0.04" />
            </geometry>
            <material name="white" />
        </visual>
    </link>


    <joint name="gripper_to_ef" type="fixed">
        <parent link="gripper" />
        <child link="ef" />
        <origin xyz="0 0 -0.2" rpy="0 3.14 -1.57"  />
    </joint>

    <link name="ef" />

</robot>
